{
 "cells": [
  {
   "cell_type": "code",
   "execution_count": 12,
   "metadata": {},
   "outputs": [
    {
     "ename": "ValueError",
     "evalue": "3 columns passed, passed data had 1 columns",
     "output_type": "error",
     "traceback": [
      "\u001b[1;31m---------------------------------------------------------------------------\u001b[0m",
      "\u001b[1;31mAssertionError\u001b[0m                            Traceback (most recent call last)",
      "File \u001b[1;32m~\\AppData\\Local\\Packages\\PythonSoftwareFoundation.Python.3.11_qbz5n2kfra8p0\\LocalCache\\local-packages\\Python311\\site-packages\\pandas\\core\\internals\\construction.py:934\u001b[0m, in \u001b[0;36m_finalize_columns_and_data\u001b[1;34m(content, columns, dtype)\u001b[0m\n\u001b[0;32m    933\u001b[0m \u001b[39mtry\u001b[39;00m:\n\u001b[1;32m--> 934\u001b[0m     columns \u001b[39m=\u001b[39m _validate_or_indexify_columns(contents, columns)\n\u001b[0;32m    935\u001b[0m \u001b[39mexcept\u001b[39;00m \u001b[39mAssertionError\u001b[39;00m \u001b[39mas\u001b[39;00m err:\n\u001b[0;32m    936\u001b[0m     \u001b[39m# GH#26429 do not raise user-facing AssertionError\u001b[39;00m\n",
      "File \u001b[1;32m~\\AppData\\Local\\Packages\\PythonSoftwareFoundation.Python.3.11_qbz5n2kfra8p0\\LocalCache\\local-packages\\Python311\\site-packages\\pandas\\core\\internals\\construction.py:981\u001b[0m, in \u001b[0;36m_validate_or_indexify_columns\u001b[1;34m(content, columns)\u001b[0m\n\u001b[0;32m    979\u001b[0m \u001b[39mif\u001b[39;00m \u001b[39mnot\u001b[39;00m is_mi_list \u001b[39mand\u001b[39;00m \u001b[39mlen\u001b[39m(columns) \u001b[39m!=\u001b[39m \u001b[39mlen\u001b[39m(content):  \u001b[39m# pragma: no cover\u001b[39;00m\n\u001b[0;32m    980\u001b[0m     \u001b[39m# caller's responsibility to check for this...\u001b[39;00m\n\u001b[1;32m--> 981\u001b[0m     \u001b[39mraise\u001b[39;00m \u001b[39mAssertionError\u001b[39;00m(\n\u001b[0;32m    982\u001b[0m         \u001b[39mf\u001b[39m\u001b[39m\"\u001b[39m\u001b[39m{\u001b[39;00m\u001b[39mlen\u001b[39m(columns)\u001b[39m}\u001b[39;00m\u001b[39m columns passed, passed data had \u001b[39m\u001b[39m\"\u001b[39m\n\u001b[0;32m    983\u001b[0m         \u001b[39mf\u001b[39m\u001b[39m\"\u001b[39m\u001b[39m{\u001b[39;00m\u001b[39mlen\u001b[39m(content)\u001b[39m}\u001b[39;00m\u001b[39m columns\u001b[39m\u001b[39m\"\u001b[39m\n\u001b[0;32m    984\u001b[0m     )\n\u001b[0;32m    985\u001b[0m \u001b[39mif\u001b[39;00m is_mi_list:\n\u001b[0;32m    986\u001b[0m     \u001b[39m# check if nested list column, length of each sub-list should be equal\u001b[39;00m\n",
      "\u001b[1;31mAssertionError\u001b[0m: 3 columns passed, passed data had 1 columns",
      "\nThe above exception was the direct cause of the following exception:\n",
      "\u001b[1;31mValueError\u001b[0m                                Traceback (most recent call last)",
      "Cell \u001b[1;32mIn[12], line 28\u001b[0m\n\u001b[0;32m     25\u001b[0m cursor\u001b[39m.\u001b[39mclose()\n\u001b[0;32m     26\u001b[0m cnx\u001b[39m.\u001b[39mclose()\n\u001b[1;32m---> 28\u001b[0m df \u001b[39m=\u001b[39m pd\u001b[39m.\u001b[39;49mDataFrame( result, columns\u001b[39m=\u001b[39;49m[\u001b[39m'\u001b[39;49m\u001b[39mmovie_id\u001b[39;49m\u001b[39m'\u001b[39;49m,\u001b[39m'\u001b[39;49m\u001b[39mtitle\u001b[39;49m\u001b[39m'\u001b[39;49m,\u001b[39m'\u001b[39;49m\u001b[39mgenre\u001b[39;49m\u001b[39m'\u001b[39;49m])\n\u001b[0;32m     29\u001b[0m df\u001b[39m.\u001b[39minfo()\n",
      "File \u001b[1;32m~\\AppData\\Local\\Packages\\PythonSoftwareFoundation.Python.3.11_qbz5n2kfra8p0\\LocalCache\\local-packages\\Python311\\site-packages\\pandas\\core\\frame.py:782\u001b[0m, in \u001b[0;36mDataFrame.__init__\u001b[1;34m(self, data, index, columns, dtype, copy)\u001b[0m\n\u001b[0;32m    780\u001b[0m     \u001b[39mif\u001b[39;00m columns \u001b[39mis\u001b[39;00m \u001b[39mnot\u001b[39;00m \u001b[39mNone\u001b[39;00m:\n\u001b[0;32m    781\u001b[0m         columns \u001b[39m=\u001b[39m ensure_index(columns)\n\u001b[1;32m--> 782\u001b[0m     arrays, columns, index \u001b[39m=\u001b[39m nested_data_to_arrays(\n\u001b[0;32m    783\u001b[0m         \u001b[39m# error: Argument 3 to \"nested_data_to_arrays\" has incompatible\u001b[39;49;00m\n\u001b[0;32m    784\u001b[0m         \u001b[39m# type \"Optional[Collection[Any]]\"; expected \"Optional[Index]\"\u001b[39;49;00m\n\u001b[0;32m    785\u001b[0m         data,\n\u001b[0;32m    786\u001b[0m         columns,\n\u001b[0;32m    787\u001b[0m         index,  \u001b[39m# type: ignore[arg-type]\u001b[39;49;00m\n\u001b[0;32m    788\u001b[0m         dtype,\n\u001b[0;32m    789\u001b[0m     )\n\u001b[0;32m    790\u001b[0m     mgr \u001b[39m=\u001b[39m arrays_to_mgr(\n\u001b[0;32m    791\u001b[0m         arrays,\n\u001b[0;32m    792\u001b[0m         columns,\n\u001b[1;32m   (...)\u001b[0m\n\u001b[0;32m    795\u001b[0m         typ\u001b[39m=\u001b[39mmanager,\n\u001b[0;32m    796\u001b[0m     )\n\u001b[0;32m    797\u001b[0m \u001b[39melse\u001b[39;00m:\n",
      "File \u001b[1;32m~\\AppData\\Local\\Packages\\PythonSoftwareFoundation.Python.3.11_qbz5n2kfra8p0\\LocalCache\\local-packages\\Python311\\site-packages\\pandas\\core\\internals\\construction.py:498\u001b[0m, in \u001b[0;36mnested_data_to_arrays\u001b[1;34m(data, columns, index, dtype)\u001b[0m\n\u001b[0;32m    495\u001b[0m \u001b[39mif\u001b[39;00m is_named_tuple(data[\u001b[39m0\u001b[39m]) \u001b[39mand\u001b[39;00m columns \u001b[39mis\u001b[39;00m \u001b[39mNone\u001b[39;00m:\n\u001b[0;32m    496\u001b[0m     columns \u001b[39m=\u001b[39m ensure_index(data[\u001b[39m0\u001b[39m]\u001b[39m.\u001b[39m_fields)\n\u001b[1;32m--> 498\u001b[0m arrays, columns \u001b[39m=\u001b[39m to_arrays(data, columns, dtype\u001b[39m=\u001b[39;49mdtype)\n\u001b[0;32m    499\u001b[0m columns \u001b[39m=\u001b[39m ensure_index(columns)\n\u001b[0;32m    501\u001b[0m \u001b[39mif\u001b[39;00m index \u001b[39mis\u001b[39;00m \u001b[39mNone\u001b[39;00m:\n",
      "File \u001b[1;32m~\\AppData\\Local\\Packages\\PythonSoftwareFoundation.Python.3.11_qbz5n2kfra8p0\\LocalCache\\local-packages\\Python311\\site-packages\\pandas\\core\\internals\\construction.py:840\u001b[0m, in \u001b[0;36mto_arrays\u001b[1;34m(data, columns, dtype)\u001b[0m\n\u001b[0;32m    837\u001b[0m     data \u001b[39m=\u001b[39m [\u001b[39mtuple\u001b[39m(x) \u001b[39mfor\u001b[39;00m x \u001b[39min\u001b[39;00m data]\n\u001b[0;32m    838\u001b[0m     arr \u001b[39m=\u001b[39m _list_to_arrays(data)\n\u001b[1;32m--> 840\u001b[0m content, columns \u001b[39m=\u001b[39m _finalize_columns_and_data(arr, columns, dtype)\n\u001b[0;32m    841\u001b[0m \u001b[39mreturn\u001b[39;00m content, columns\n",
      "File \u001b[1;32m~\\AppData\\Local\\Packages\\PythonSoftwareFoundation.Python.3.11_qbz5n2kfra8p0\\LocalCache\\local-packages\\Python311\\site-packages\\pandas\\core\\internals\\construction.py:937\u001b[0m, in \u001b[0;36m_finalize_columns_and_data\u001b[1;34m(content, columns, dtype)\u001b[0m\n\u001b[0;32m    934\u001b[0m     columns \u001b[39m=\u001b[39m _validate_or_indexify_columns(contents, columns)\n\u001b[0;32m    935\u001b[0m \u001b[39mexcept\u001b[39;00m \u001b[39mAssertionError\u001b[39;00m \u001b[39mas\u001b[39;00m err:\n\u001b[0;32m    936\u001b[0m     \u001b[39m# GH#26429 do not raise user-facing AssertionError\u001b[39;00m\n\u001b[1;32m--> 937\u001b[0m     \u001b[39mraise\u001b[39;00m \u001b[39mValueError\u001b[39;00m(err) \u001b[39mfrom\u001b[39;00m \u001b[39merr\u001b[39;00m\n\u001b[0;32m    939\u001b[0m \u001b[39mif\u001b[39;00m \u001b[39mlen\u001b[39m(contents) \u001b[39mand\u001b[39;00m contents[\u001b[39m0\u001b[39m]\u001b[39m.\u001b[39mdtype \u001b[39m==\u001b[39m np\u001b[39m.\u001b[39mobject_:\n\u001b[0;32m    940\u001b[0m     contents \u001b[39m=\u001b[39m convert_object_array(contents, dtype\u001b[39m=\u001b[39mdtype)\n",
      "\u001b[1;31mValueError\u001b[0m: 3 columns passed, passed data had 1 columns"
     ]
    }
   ],
   "source": [
    "import mysql.connector\n",
    "import pandas as pd\n",
    "\n",
    "try:\n",
    "    cnx = mysql.connector.connect(\n",
    "        host=\"localhost\",\n",
    "        port=3306,\n",
    "        user=\"root\",\n",
    "        password='root',\n",
    "        database='movielens'\n",
    "    )\n",
    "\n",
    "\n",
    "\n",
    "    cursor = cnx.cursor()\n",
    "\n",
    "    query = \"select * from movies\"\n",
    "    cursor.execute(\"show tables\")\n",
    "    result = cursor.fetchall()\n",
    "\n",
    "except Exception as e:\n",
    "    print(e)\n",
    "finally:\n",
    "\n",
    "    cursor.close()\n",
    "    cnx.close()\n",
    "\n",
    "    df = pd.DataFrame( result, columns=['movie_id','title','genre'])\n",
    "    df.info()\n"
   ]
  }
 ],
 "metadata": {
  "kernelspec": {
   "display_name": "Python 3",
   "language": "python",
   "name": "python3"
  },
  "language_info": {
   "codemirror_mode": {
    "name": "ipython",
    "version": 3
   },
   "file_extension": ".py",
   "mimetype": "text/x-python",
   "name": "python",
   "nbconvert_exporter": "python",
   "pygments_lexer": "ipython3",
   "version": "3.11.5"
  },
  "orig_nbformat": 4
 },
 "nbformat": 4,
 "nbformat_minor": 2
}
